Workbook

Sheet Índice
A1: HouseGreen · Planificación ágil, sprints y pruebas
A4: Sección | B4: Hoja | C4: Contenido
A5: G | B5: G1 Squad | C5: Integrantes, roles Scrum, responsabilidades y capacidad; ceremonias y artefactos
A6: G | B6: G2 Épicas | C6: Épicas con descripción, priorización, historias y puntos
A7: G | B7: G3 Historias de usuario | C7: Historias de usuario en la plantilla: enunciado y criterios de aceptación por escenario
A8: G | B8: G4 Product Backlog | C8: Product Backlog priorizado por valor, urgencia y esfuerzo
A9: G | B9: G5 Estimación | C9: Patrón de comparación para estimar y capacidad del equipo
A10: G | B10: G6 Entregables | C10: Entregables formales con su release y estado
A11: G | B11: G7 Story Map | C11: User Story Map por actividad y release
A12: G | B12: G8 Releases | C12: Release Planning
A13: H | B13: H1 Sprints | C13: Calendario de los 7 sprints (un ciclo por sprint) y horas por integrante
A14: H | B14: H2 Definition of Done | C14: Definition of Done
A15: H | B15: H3 Sprint 1 | C15: Sprint 1 (Documentación fase 1): backlog, avance día a día y burndown
... A32: I | B32: I5 Defectos | C32: Gestión de defectos

Sheet G1 Squad
A1: Squad y responsabilidades
A4: Integrante | B4: Rol Scrum | C4: Responsabilidades | D4: Dedicación (h por semana)
A5: Matías Negrete | B5: Product Owner (documentación) | C5: Define y ordena el Product Backlog según el valor para el inversionista; redacta los criterios de aceptación; acepta o rechaza cada incremento en la Sprint Review (A/R); hace la documentación del proyecto (informe, prototipo, procesos, vistas 4+1 y documentos de dirección) y creó la base de datos junto a José Pizarro. | D5: 10
A6: José Pizarro | B6: Scrum Master (web y backend) | C6: Facilita el Sprint Planning, la Daily, la Review y la Retrospective; mantiene el tablero, el burndown y el registro de impedimentos. Desarrolla la página web, la API, la carga automática de remates (scrapeo) y la conexión de la base de datos con la página; creó la base de datos junto a Matías Negrete. | D6: 10
A7: Basthian Bascuñan | B7: Development Team (aplicación móvil) | C7: Construye y prueba la aplicación móvil del inversionista (front-end terminado el 03-10-2026) y su conexión con la API en Android Studio; estima las historias y propone mejoras técnicas. | D7: 10
A8: Capacidad del equipo por semana (h) | D8: =SUM(D5:D7) -> 30
A10: Responsabilidades por ceremonia y artefacto
A11: Ceremonia o artefacto | B11: Cuándo | C11: Resultado esperado | D11: Responsable | E11: Participan
A12: Sprint Planning | B12: Primer día del sprint · 1 h | C12: Sprint Goal, historias comprometidas y tareas estimadas | D12: José Pizarro | E12: Todo el equipo
A13: Daily Meeting | B13: Cada día · 15 min | C13: Avance, plan del día y bloqueos (pasan al Impediment Log) | D13: José Pizarro | E13: Todo el equipo
A14: Refinamiento del backlog | B14: Una vez por semana · 30 min | C14: Historias con criterios de aceptación y estimación | D14: Matías Negrete | E14: Todo el equipo
A15: Sprint Review | B15: Último día del sprint · 45 min | C15: Incremento aceptado o rechazado (A/R) y backlog ajustado | D15: Matías Negrete | E15: Equipo, docente y usuarios invitados
A16: Retrospective | B16: Último día del sprint · 30 min | C16: Tres mejoras concretas para el sprint siguiente | D16: José Pizarro | E16: Todo el equipo
A17: Product Backlog | B17: Continuo | C17: Orden por valor, urgencia y esfuerzo | D17: Matías Negrete | E17: Todo el equipo
A18: Sprint Backlog, Scrum Board y Burndown | B18: Se actualizan cada día | C18: Avance visible del sprint | D18: José Pizarro | E18: Todo el equipo
A19: Definition of Done | B19: En cada tarea e historia | C19: Calidad pareja del incremento | D19: José Pizarro | E19: Todo el equipo
A20: Incremento (código y pruebas) | B20: Cada sprint | C20: Software que cumple la Definition of Done | D20: José Pizarro y Basthian Bascuñan | E20: Matías Negrete (valida)

Sheet G2 Épicas
A1: Épicas
A4: ID | B4: Épica | C4: Descripción | D4: RF | E4: Entregables | F4: Priorización | G4: Historias | H4: Puntos
A5: E1 | B5: Acceso y seguridad | C5: El usuario se registra, inicia sesión y recupera su acceso; el administrador entra con segundo factor; cada rol ve solo lo que le corresponde y las acciones críticas quedan auditadas. | D5: RF-01, 02, 03 | E5: 4, 5, 17 | F5: 100 | G5: =COUNTIF('G4 Product Backlog'!$C$5:$C$27,A5) -> 4 | H5: =SUMIF('G4 Product Backlog'!$C$5:$C$27,A5,'G4 Product Backlog'!$J$5:$J$27) -> 18
A6: E2 | B6: Propiedades y búsqueda | C6: El inversionista ve el catálogo de remates vigentes, abre la ficha de cada propiedad y filtra por comuna, precio, tipo y zona. | D6: RF-04, 05, 06 | E6: 1, 6 | F6: 100 | G6: =COUNTIF('G4 Product Backlog'!$C$5:$C$27,A6) -> 2 | H6: =SUMIF('G4 Product Backlog'!$C$5:$C$27,A6,'G4 Product Backlog'!$J$5:$J$27) -> 10
A7: E3 | B7: Motor de reglas y semáforo | C7: Cada propiedad recibe su semáforo de forma automática, con la justificación factor por factor, reglas de veto y registro de cada evaluación. | D7: RF-08, 09, 10 | E7: 8, 9, 10 | F7: 100 | G7: =COUNTIF('G4 Product Backlog'!$C$5:$C$27,A7) -> 3 | H7: =SUMIF('G4 Product Backlog'!$C$5:$C$27,A7,'G4 Product Backlog'!$J$5:$J$27) -> 21
A8: E4 | B8: Seguimiento y alertas | C8: El inversionista guarda propiedades, crea filtros y recibe alertas cuando aparece una oportunidad o cambia una que sigue. | D8: RF-07, 11, 12 | E8: 11, 13 | F8: 80 | G8: =COUNTIF('G4 Product Backlog'!$C$5:$C$27,A8) -> 3 | H8: =SUMIF('G4 Product Backlog'!$C$5:$C$27,A8,'G4 Product Backlog'!$J$5:$J$27) -> 14
A9: E5 | B9: Ingesta de datos | C9: Los remates se cargan solos desde rematesinmobiliarios.cl, se validan y se normalizan, sin duplicados. | D9: RF-14 | E9: 14 | F9: 100 | G9: =COUNTIF('G4 Product Backlog'!$C$5:$C$27,A9) -> 1 | H9: =SUMIF('G4 Product Backlog'!$C$5:$C$27,A9,'G4 Product Backlog'!$J$5:$J$27) -> 13
A10: E6 | B10: Geografía y mapa | C10: Las propiedades se ubican por comuna en un mapa, con la cobertura del servicio y el índice de seguridad comunal. | D10: RF-06 | E10: 7, 12 | F10: 80 | G10: =COUNTIF('G4 Product Backlog'!$C$5:$C$27,A10) -> 1 | H10: =SUMIF('G4 Product Backlog'!$C$5:$C$27,A10,'G4 Product Backlog'!$J$5:$J$27) -> 5
A11: E7 | B11: Administración y métricas | C11: El administrador edita fotos y descripción, ve quién vio y guardó cada publicación, envía anuncios y responde opiniones; el analista revisa métricas en modo solo lectura. | D11: RF-14, 15 | E11: 15 | F11: 50 | G11: =COUNTIF('G4 Product Backlog'!$C$5:$C$27,A11) -> 4 | H11: =SUMIF('G4 Product Backlog'!$C$5:$C$27,A11,'G4 Product Backlog'!$J$5:$J$27) -> 21
A12: E8 | B12: App móvil | C12: El inversionista usa HouseGreen en el teléfono: catálogo, detalle, guardados y avisos push. | D12: RF-06, 07, 11 | E12: 2 | F12: 80 | G12: =COUNTIF('G4 Product Backlog'!$C$5:$C$27,A12) -> 1 | H12: =SUMIF('G4 Product Backlog'!$C$5:$C$27,A12,'G4 Product Backlog'!$J$5:$J$27) -> 13
A13: E9 | B13: Plataforma y calidad | C13: API documentada, base de datos, pruebas automatizadas, despliegue de demostración y validación con usuarios. | D13: RF-13, 16 | E13: 3, 16, 18, 19 | F13: 100 | G13: =COUNTIF('G4 Product Backlog'!$C$5:$C$27,A13) -> 4 | H13: =SUMIF('G4 Product Backlog'!$C$5:$C$27,A13,'G4 Product Backlog'!$J$5:$J$27) -> 21
A14: Total | G14: =SUM(G5:G13) -> 23 | H14: =SUM(H5:H13) -> 136
B16: Escala de priorización
B17: Priorización | C17: Significado
B18: 100 | C18: Imprescindible para el MVP (Release 1)
B19: 80 | C19: Necesaria para la propuesta completa
B20: 50 | C20: Complementa la operación

Sheet G3 Historias de usuario
A1: Historias de usuario
A4: Enunciado de la historia | E4: Criterios de aceptación
A5: ID de la historia | B5: Rol | C5: Funcionalidad | D5: Resultado | E5: N.º de escenario | F5: Criterio de aceptación (título) | G5: Contexto | H5: Evento | I5: Comportamiento esperado
A6: HU-01 (E1 · 5 pts) | B6: Inversionista | C6: Registrarme e iniciar sesión con correo y contraseña | D6: Acceder de forma segura a la plataforma | E6: 1 | F6: Registro válido | G6: El correo no está registrado | H6: Cuando envío el formulario con un correo válido y una contraseña de 8 o más caracteres | I6: Se crea la cuenta con rol inversionista y la contraseña se guarda cifrada con bcrypt
E7: 2 | F7: Correo ya registrado | G7: Existe una cuenta con ese correo | H7: Cuando intento registrarme | I7: El sistema rechaza el registro con un mensaje claro y no crea otra cuenta
E8: 3 | F8: Contraseña incorrecta | G8: Tengo una cuenta creada | H8: Cuando inicio sesión con una contraseña errónea | I8: Responde 401 con un mensaje genérico, sin revelar si el correo existe
A9: HU-02 (E2 · 5 pts) | B9: Inversionista | C9: Ver el catálogo de remates vigentes | D9: Conocer las oportunidades disponibles | E9: 1 | F9: Remates vigentes | G9: Hay propiedades activas | H9: Cuando abro el catálogo | I9: Veo cada propiedad con comuna, tipo, precio mínimo, fecha del remate, zona y puntaje del semáforo
E10: 2 | F10: Sin remates | G10: No hay propiedades activas | H10: Cuando abro el catálogo | I10: Veo el mensaje «No hay remates vigentes», sin errores
E11: 3 | F11: Remate terminado | G11: La propiedad ya fue rematada o su fecha pasó | H11: Cuando abro el catálogo | I11: La propiedad no aparece entre las vigentes
A12: HU-03 (E3 · 8 pts) | B12: Inversionista | C12: Que cada propiedad tenga su semáforo calculado automáticamente | D12: Saber de inmediato su nivel de riesgo | E12: 1 | F12: Propiedad completa | G12: La propiedad tiene los datos de los 4 factores | H12: Cuando se guarda o se actualiza | I12: Se calcula el puntaje de 0 a 8 y la zona (6 a 8 verde, 3 a 5 amarilla, 0 a 2 roja) y se guarda la evaluación. Reglas del 05-10-2026 (4 factores): falta aplicarlas en la base de datos
E13: 2 | F13: Dato faltante | G13: Falta un factor, por ejemplo los comparables | H13: Cuando se evalúa | I13: Ese factor se evalúa con 0 puntos y se muestra «Por verificar», porque sin el dato no se puede sacar una conclusión
E14: 3 | F14: Veto | G14: Tiene usufructo vitalicio, herencia no resuelta, prohibición de expropiación o descuento real menor a 15 % | H14: Cuando se evalúa | I14: Queda en zona roja por veto y se guarda el motivo
A15: HU-04 (E9 · 3 pts) | B15: Equipo de desarrollo | C15: Una API REST documentada en /api/v1 | D15: Que la web, la app y el panel usen la misma lógica | E15: 1 | F15: Documentación | G15: La API está en ejecución | H15: Cuando abro /docs | I15: Todos los endpoints de /api/v1 aparecen documentados (OpenAPI) con sus esquemas
E16: 2 | F16: Datos inválidos | G16: Envío un cuerpo con datos inválidos | H16: Cuando llamo a un endpoint | I16: Responde 422 con {código, mensaje}, sin detalles internos
E17: 3 | F17: Sin token | G17: El endpoint está protegido | H17: Cuando lo llamo sin token o con uno vencido | I17: Responde 401
A18: HU-05 (E3 · 5 pts) | B18: Inversionista | C18: Ver en el detalle la justificación del semáforo factor por factor | D18: Confiar en la clasificación | E18: 1 | F18: Detalle con justificación | G18: La propiedad tiene una evaluación | H18: Cuando abro el detalle | I18: Veo los 4 factores con su valor, zona, puntos y fuente, y el puntaje total
E19: 2 | F19: Propiedad vetada | G19: La evaluación tiene un veto | H19: Cuando abro el detalle | I19: Veo «Zona roja por veto» y el motivo
E20: 3 | F20: Historial | G20: La propiedad tuvo evaluaciones anteriores | H20: Cuando abro el historial | I20: Veo la fecha, el puntaje y la zona de cada evaluación
A21: HU-06 (E2 · 5 pts) | B21: Inversionista | C21: Filtrar por comuna, precio, tipo y zona | D21: Encontrar lo que calza con mi estrategia | E21: 1 | F21: Filtro combinado | G21: Hay propiedades de varias comunas y precios | H21: Cuando filtro por Maipú y precio hasta $80.000.000 | I21: Solo aparecen las que cumplen ambos filtros, en 2 segundos o menos
E22: 2 | F22: Filtro por zona | G22: Hay propiedades en las tres zonas | H22: Cuando filtro por zona verde | I22: Solo aparecen propiedades en zona verde
E23: 3 | F23: Sin coincidencias | G23: Ninguna propiedad cumple los filtros | H23: Cuando aplico los filtros | I23: Veo «Sin resultados» y la opción para limpiar los filtros
A24: HU-07 (E4 · 3 pts) | B24: Inversionista | C24: Guardar propiedades | D24: Seguirlas hasta el día del remate | E24: 1 | F24: Guardar | G24: Estoy en el catálogo o en el detalle | H24: Cuando toco «Guardar» | I24: La propiedad aparece en Guardados y se mantiene al cerrar y volver a abrir la sesión
E25: 2 | F25: Quitar | G25: Tengo una propiedad guardada | H25: Cuando la quito y confirmo | I25: Desaparece de mi lista
E26: 3 | F26: Datos ajenos | G26: Otro usuario tiene propiedades guardadas | H26: Cuando pido sus guardados cambiando el id | I26: Responde 403 o 404, sin mostrar datos ajenos
A27: HU-08 (E7 · 3 pts) | B27: Administrador | C27: Editar las fotos y la descripción de una publicación | D27: Mejorar su presentación sin alterar los datos del remate | E27: 1 | F27: Editar descripción | G27: Estoy en una publicación | H27: Cuando guardo una descripción de hasta 1.000 caracteres | I27: La ficha muestra la nueva descripción y el cambio queda auditado
E28: 2 | F28: Fotos | G28: Estoy en una publicación | H28: Cuando subo, ordeno o elijo la portada (hasta 15 fotos) | I28: La ficha muestra las fotos en ese orden, con la portada elegida
E29: 3 | F29: Datos del remate | G29: Estoy en una publicación | H29: Cuando intento cambiar el precio, la fecha o el tribunal | I29: No es posible: esos campos no se editan y la API responde 403
A30: HU-09 (E1 · 5 pts) | B30: Administrador | C30: Iniciar sesión con un segundo factor | D30: Proteger el panel de administración | E30: 1 | F30: Código válido | G30: Tengo el segundo factor activo | H30: Cuando ingreso correo, contraseña y un código TOTP vigente | I30: Entro al panel
E31: 2 | F31: Código vencido o usado | G31: Tengo el segundo factor activo | H31: Cuando ingreso un código vencido o ya usado | I31: Se niega el acceso y el intento queda en la auditoría
E32: 3 | F32: Intentos fallidos | G32: Fallé 5 veces seguidas | H32: Cuando intento entrar de nuevo | I32: La cuenta queda bloqueada 15 minutos
A33: HU-10 (E5 · 13 pts) | B33: Administrador | C33: Que los remates se carguen solos desde https://www.rematesinmobiliarios.cl/ cada 6 horas | D33: Que el catálogo esté al día | E33: 1 | F33: Carga programada | G33: El planificador está activo | H33: Cuando se cumplen 6 horas desde la última carga | I33: Se leen los remates publicados, se cargan los nuevos y se registra la ejecución con cargados y errores
E34: 2 | F34: Aviso incompleto | G34: Un aviso viene sin rol de avalúo | H34: Cuando se procesa | I34: Se descarta, queda registrado el error y la carga continúa
E35: 3 | F35: Aviso repetido | G35: El aviso ya fue cargado | H35: Cuando se lee otra vez | I35: No se duplica la propiedad; se actualiza si cambió
A36: HU-11 (E3 · 8 pts) | B36: Administrador | C36: Configurar umbrales, vetos e índice comunal | D36: Ajustar el semáforo sin tocar el código | E36: 1 | F36: Cambiar un umbral | G36: Estoy en Reglas del semáforo | H36: Cuando cambio el umbral verde del factor 1 y guardo | I36: Se crea una nueva versión de reglas y se recalculan las publicaciones activas
E37: 2 | F37: Umbral inválido | G37: Estoy editando un factor | H37: Cuando dejo el umbral verde por debajo del rojo | I37: No se guarda y el sistema explica el error
E38: 3 | F38: Índice comunal | G38: Estoy en Seguridad por comuna | H38: Cuando cambio el nivel de una comuna | I38: Queda con su fecha de vigencia y se recalculan sus propiedades
A39: HU-12 (E1 · 3 pts) | B39: Inversionista | C39: Recuperar mi contraseña por correo | D39: No perder el acceso a mi cuenta | E39: 1 | F39: Solicitud | G39: Olvidé mi contraseña | H39: Cuando ingreso mi correo | I39: Veo el mismo mensaje exista o no la cuenta; si existe, llega un enlace de un solo uso que vence en 30 minutos
E40: 2 | F40: Enlace vencido o usado | G40: Recibí un enlace | H40: Cuando lo abro después de 30 minutos o por segunda vez | I40: Se rechaza y puedo pedir uno nuevo
A41: HU-13 (E4 · 8 pts) | B41: Inversionista | C41: Recibir alertas cuando aparezca una propiedad que calce con mis filtros | D41: No perder oportunidades | E41: 1 | F41: Nueva coincidencia | G41: Tengo un filtro guardado y activo | H41: Cuando la ingesta carga una propiedad que calza | I41: Recibo una alerta (app, push o correo) en menos de 5 minutos
E42: 2 | F42: Filtro inactivo | G42: Desactivé mi filtro | H42: Cuando llega una propiedad que calza | I42: No recibo alerta
...

Sheet G4 Product Backlog
A1: Product Backlog priorizado
A4: Orden | B4: ID | C4: Épica | D4: Historia de usuario | E4: RF o entregable | F4: Valor (1 a 5) | G4: Urgencia (1 a 5) | H4: Puntaje (V × U) | I4: Prioridad | J4: Puntos | K4: Sprint (plan 24-09) | L4: Sprint (al 04-10) | M4: Release | N4: Estado
A5: 1 | B5: HU-01 | C5: E1 | D5: Como inversionista, quiero registrarme e iniciar sesión con correo y contraseña, para acceder de forma segura a la plataforma. | E5: RF-01 | F5: 5 | G5: 5 | H5: =F5*G5 -> 25 | I5: =IF(H5>=16,"Alta",IF(H5>=9,"Media","Baja")) -> Alta | J5: 5 | K5: 3 | L5: 4 | M5: =IF(L5<=5,"R1",IF(L5<=7,"R2","R3")) -> R1 | N5: Hecho
A6: 2 | B6: HU-02 | C6: E2 | D6: Como inversionista, quiero ver el catálogo de remates vigentes, para conocer las oportunidades disponibles. | E6: RF-04 | F6: 5 | G6: 5 | H6: =F6*G6 -> 25 | I6: =IF(H6>=16,"Alta",IF(H6>=9,"Media","Baja")) -> Alta | J6: 5 | K6: 3 | L6: 5 | M6: =IF(L6<=5,"R1",IF(L6<=7,"R2","R3")) -> R1 | N6: Hecho
A7: 3 | B7: HU-03 | C7: E3 | D7: Como inversionista, quiero que cada propiedad tenga su semáforo calculado automáticamente, para saber de inmediato su nivel de riesgo. | E7: RF-08 | F7: 5 | G7: 5 | H7: =F7*G7 -> 25 | I7: =IF(H7>=16,"Alta",IF(H7>=9,"Media","Baja")) -> Alta | J7: 8 | K7: 3 | L7: 4 | M7: =IF(L7<=5,"R1",IF(L7<=7,"R2","R3")) -> R1 | N7: Hecho
A8: 4 | B8: HU-07 | C8: E4 | D8: Como inversionista, quiero guardar propiedades, para seguirlas hasta el día del remate. | E8: RF-07 | F8: 4 | G8: 3 | H8: =F8*G8 -> 12 | I8: =IF(H8>=16,"Alta",IF(H8>=9,"Media","Baja")) -> Media | J8: 3 | K8: 4 | L8: 5 | M8: =IF(L8<=5,"R1",IF(L8<=7,"R2","R3")) -> R1 | N8: Hecho
A9: 5 | B9: HU-04 | C9: E9 | D9: Como equipo de desarrollo, quiero una API REST documentada en /api/v1, para que la web, la app y el panel usen la misma lógica. | E9: RF-13 | F9: 4 | G9: 5 | H9: =F9*G9 -> 20 | I9: =IF(H9>=16,"Alta",IF(H9>=9,"Media","Baja")) -> Alta | J9: 3 | K9: 4 | L9: 6 | M9: =IF(L9<=5,"R1",IF(L9<=7,"R2","R3")) -> R2 | N9: Por hacer
A10: 6 | B10: HU-05 | C10: E3 | D10: Como inversionista, quiero ver en el detalle la justificación del semáforo factor por factor, para confiar en la clasificación. | E10: RF-09 | F10: 5 | G10: 4 | H10: =F10*G10 -> 20 | I10: =IF(H10>=16,"Alta",IF(H10>=9,"Media","Baja")) -> Alta | J10: 5 | K10: 4 | L10: 4 | M10: =IF(L10<=5,"R1",IF(L10<=7,"R2","R3")) -> R1 | N10: Hecho
A11: 7 | B11: HU-06 | C11: E2 | D11: Como inversionista, quiero filtrar por comuna, precio, tipo y zona, para encontrar lo que calza con mi estrategia. | E11: RF-06 | F11: 4 | G11: 4 | H11: =F11*G11 -> 16 | I11: =IF(H11>=16,"Alta",IF(H11>=9,"Media","Baja")) -> Alta | J11: 5 | K11: 4 | L11: 5 | M11: =IF(L11<=5,"R1",IF(L11<=7,"R2","R3")) -> R1 | N11: Hecho
A12: 8 | B12: HU-08 | C12: E7 | D12: Como administrador, quiero editar las fotos y la descripción de una publicación, para mejorar su presentación sin alterar los datos del remate. | E12: RF-14 | F12: 3 | G12: 4 | H12: =F12*G12 -> 12 | I12: =IF(H12>=16,"Alta",IF(H12>=9,"Media","Baja")) -> Media | J12: 3 | K12: 4 | L12: 4 | M12: =IF(L12<=5,"R1",IF(L12<=7,"R2","R3")) -> R1 | N12: Hecho
A13: 9 | B13: HU-23 | C13: E7 | D13: Como administrador, quiero ver cuántas personas vieron y guardaron cada publicación, para enviar anuncios a los interesados. | E13: RF-15 | F13: 3 | G13: 3 | H13: =F13*G13 -> 9 | I13: =IF(H13>=16,"Alta",IF(H13>=9,"Media","Baja")) -> Media | J13: 5 | K13: Nueva | L13: 4 | M13: =IF(L13<=5,"R1",IF(L13<=7,"R2","R3")) -> R1 | N13: Hecho
A14: 10 | B14: HU-10 | C14: E5 | D14: Como administrador, quiero que los remates se carguen solos desde https://www.rematesinmobiliarios.cl/ cada 6 horas, para que el catálogo esté al día. | E14: RF-14 | F14: 5 | G14: 4 | H14: =F14*G14 -> 20 | I14: =IF(H14>=16,"Alta",IF(H14>=9,"Media","Baja")) -> Alta | J14: 13 | K14: 5 | L14: 4 | M14: =IF(L14<=5,"R1",IF(L14<=7,"R2","R3")) -> R1 | N14: Hecho
A15: 11 | B15: HU-09 | C15: E1 | D15: Como administrador, quiero iniciar sesión con un segundo factor, para proteger el panel de administración. | E15: RF-02 | F15: 4 | G15: 4 | H15: =F15*G15 -> 16 | I15: =IF(H15>=16,"Alta",IF(H15>=9,"Media","Baja")) -> Alta | J15: 5 | K15: 5 | L15: — | M15: =IF(L15<=5,"R1",IF(L15<=7,"R2","R3")) -> R3 | N15: Por hacer
A16: 12 | B16: HU-12 | C16: E1 | D16: Como inversionista, quiero recuperar mi contraseña por correo, para no perder el acceso a mi cuenta. | E16: RF-03 | F16: 3 | G16: 3 | H16: =F16*G16 -> 9 | I16: =IF(H16>=16,"Alta",IF(H16>=9,"Media","Baja")) -> Media | J16: 3 | K16: 5 | L16: 5 | M16: =IF(L16<=5,"R1",IF(L16<=7,"R2","R3")) -> R1 | N16: En curso
A17: 13 | B17: HU-11 | C17: E3 | D17: Como administrador, quiero configurar umbrales, vetos e índice comunal, para ajustar el semáforo sin tocar el código. | E17: RF-10 | F17: 4 | G17: 3 | H17: =F17*G17 -> 12 | I17: =IF(H17>=16,"Alta",IF(H17>=9,"Media","Baja")) -> Media | J17: 8 | K17: 6 | L17: — | M17: =IF(L17<=5,"R1",IF(L17<=7,"R2","R3")) -> R3 | N17: Descartada
A18: 14 | B18: HU-13 | C18: E4 | D18: Como inversionista, quiero recibir alertas cuando aparezca una propiedad que calce con mis filtros, para no perder oportunidades. | E18: RF-11 | F18: 4 | G18: 3 | H18: =F18*G18 -> 12 | I18: =IF(H18>=16,"Alta",IF(H18>=9,"Media","Baja")) -> Media | J18: 8 | K18: 6 | L18: 6 | M18: =IF(L18<=5,"R1",IF(L18<=7,"R2","R3")) -> R2 | N18: Por hacer
A19: 15 | B19: HU-15 | C19: E6 | D19: Como inversionista, quiero ver los remates en un mapa por comuna, para ubicar las oportunidades. | E19: Entreg. 7 y 12 | F19: 3 | G19: 3 | H19: =F19*G19 -> 9 | I19: =IF(H19>=16,"Alta",IF(H19>=9,"Media","Baja")) -> Media | J19: 5 | K19: 6 | L19: 5 | M19: =IF(L19<=5,"R1",IF(L19<=7,"R2","R3")) -> R1 | N19: En curso
A20: 16 | B20: HU-14 | C20: E4 | D20: Como inversionista, quiero ver el historial de alertas, para revisar cambios de precio y de zona. | E20: RF-12 | F20: 2 | G20: 3 | H20: =F20*G20 -> 6 | I20: =IF(H20>=16,"Alta",IF(H20>=9,"Media","Baja")) -> Baja | J20: 3 | K20: 6 | L20: 6 | M20: =IF(L20<=5,"R1",IF(L20<=7,"R2","R3")) -> R2 | N20: Por hacer
A21: 17 | B21: HU-19 | C21: E9 | D21: Como responsable de calidad, quiero pruebas automatizadas que corran en cada cambio, para detectar errores antes de entregar. | E21: RF-16 | F21: 4 | G21: 4 | H21: =F21*G21 -> 16 | I21: =IF(H21>=16,"Alta",IF(H21>=9,"Media","Baja")) -> Alta | J21: 8 | K21: 7 | L21: 6 | M21: =IF(L21<=5,"R1",IF(L21<=7,"R2","R3")) -> R2 | N21: Por hacer
A22: 18 | B22: HU-22 | C22: E1 | D22: Como administrador, quiero que las acciones críticas queden auditadas y que la API tenga límites de uso, para proteger la plataforma. | E22: Entreg. 17 | F22: 4 | G22: 4 | H22: =F22*G22 -> 16 | I22: =IF(H22>=16,"Alta",IF(H22>=9,"Media","Baja")) -> Alta | J22: 5 | K22: 7 | L22: — | M22: =IF(L22<=5,"R1",IF(L22<=7,"R2","R3")) -> R3 | N22: Por hacer
A23: 19 | B23: HU-17 | C23: E7 | D23: Como analista, quiero ver métricas de subastas, usuarios y alcance en modo solo lectura, para evaluar la tracción del producto. | E23: RF-15 | F23: 2 | G23: 4 | H23: =F23*G23 -> 8 | I23: =IF(H23>=16,"Alta",IF(H23>=9,"Media","Baja")) -> Baja | J23: 8 | K23: 7 | L23: 5 | M23: =IF(L23<=5,"R1",IF(L23<=7,"R2","R3")) -> R1 | N23: En curso
A24: 20 | B24: HU-18 | C24: E7 | D24: Como administrador, quiero enviar anuncios y responder opiniones autorizadas, para comunicarme con los usuarios. | E24: Entreg. 15 | F24: 2 | G24: 3 | H24: =F24*G24 -> 6 | I24: =IF(H24>=16,"Alta",IF(H24>=9,"Media","Baja")) -> Baja | J24: 5 | K24: 7 | L24: 5 | M24: =IF(L24<=5,"R1",IF(L24<=7,"R2","R3")) -> R1 | N24: En curso
A25: 21 | B25: HU-20 | C25: E9 | D25: Como equipo de desarrollo, quiero desplegar la web, la API, el worker y la base en la nube, para demostrar la solución funcionando. | E25: Entreg. 19 | F25: 4 | G25: 4 | H25: =F25*G25 -> 16 | I25: =IF(H25>=16,"Alta",IF(H25>=9,"Media","Baja")) -> Alta | J25: 5 | K25: 8 | L25: 6 | M25: =IF(L25<=5,"R1",IF(L25<=7,"R2","R3")) -> R2 | N25: Por hacer
A26: 22 | B26: HU-16 | C26: E8 | D26: Como inversionista, quiero usar HouseGreen en el teléfono y recibir avisos push, para revisar oportunidades en terreno. | E26: Entreg. 2 | F26: 4 | G26: 3 | H26: =F26*G26 -> 12 | I26: =IF(H26>=16,"Alta",IF(H26>=9,"Media","Baja")) -> Media | J26: 13 | K26: 8 | L26: 6 | M26: =IF(L26<=5,"R1",IF(L26<=7,"R2","R3")) -> R2 | N26: En curso
A27: 23 | B27: HU-21 | C27: E9 | D27: Como Product Owner, quiero validar el producto con inversionistas, para confirmar que resuelve el problema. | E27: Objetivo 7 | F27: 5 | G27: 4 | H27: =F27*G27 -> 20 | I27: =IF(H27>=16,"Alta",IF(H27>=9,"Media","Baja")) -> Alta | J27: 5 | K27: 9 | L27: 7 | M27: =IF(L27<=5,"R1",IF(L27<=7,"R2","R3")) -> R2 | N27: Por hacer
A28: Total | J28: =SUM(J5:J27) -> 136
A30: Puntos por sprint
A31: Sprint | B31: Puntos | C31: Release
A32: 1 | B32: =SUMIF($L$5:$L$27,A32,$J$5:$J$27) -> 0 | C32: —
A33: 2 | B33: =SUMIF($L$5:$L$27,A33,$J$5:$J$27) -> 0 | C33: —
A34: 3 | B34: =SUMIF($L$5:$L$27,A34,$J$5:$J$27) -> 0 | C34: —
A35: 4 | B35: =SUMIF($L$5:$L$27,A35,$J$5:$J$27) -> 39 | C35: R1
A36: 5 | B36: =SUMIF($L$5:$L$27,A36,$J$5:$J$27) -> 34 | C36: R1
A37: 6 | B37: =SUMIF($L$5:$L$27,A37,$J$5:$J$27) -> 40 | C37: R2
A38: 7 | B38: =SUMIF($L$5:$L$27,A38,$J$5:$J$27) -> 5 | C38: R2

Sheet G5 Estimación
A1: Estimación: patrón de comparación
A4: Puntos | B4: Complejidad | C4: Esfuerzo | D4: Incertidumbre y dependencias | E4: Historia de referencia
A5: 3 | B5: Baja | C5: Una tarde o menos por integrante | D5: Sin dependencias ni dudas técnicas | E5: HU-07 · Guardar propiedades
A6: 5 | B6: Media | C6: Un endpoint, su pantalla y sus pruebas | D6: Pocas dependencias | E6: HU-01 · Registro e inicio de sesión
A7: 8 | B7: Alta | C7: Varias reglas de negocio y casos borde | D7: Depende de datos de varias tablas | E7: HU-03 · Semáforo automático
A8: 13 | B8: Muy alta | C8: Integración con un sistema externo | D8: Alta incertidumbre: la fuente puede cambiar o fallar | E8: HU-10 · Carga automática de remates
C10: Capacidad y velocidad
C11: Parámetro | D11: Valor
C12: Integrantes del equipo | D12: =COUNTA('G1 Squad'!A5:A7) -> 3
C13: Horas por semana de cada integrante | D13: 10
C14: Semanas del proyecto | D14: 11
C15: Horas disponibles del proyecto | D15: =D12*D13*D14 -> 330
C16: Puntos del plan de entrega (sprints 4 a 7) | D16: =SUM('H1 Sprints'!F5:F11) -> 118
C17: Horas disponibles por punto | D17: =ROUND(D15/D16,1) -> 2.8
C18: Técnica de estimación | D18: Planning Poker con la serie de Fibonacci (1, 2, 3, 5, 8, 13)

Sheet G6 Entregables
A1: Definición de entregables
A4: N.º | B4: Entregable | C4: Épica | D4: Historias | E4: Release | F4: Estado al 04-10 | G4: Evidencia
A5: 1 | B5: Plataforma web HouseGreen | C5: E2 | D5: HU-02, 05, 06 | E5: R1 | F5: Implementado | G5: React 19 + Vite: catálogo desde la API, sesión con /auth/me, detalle y guardados por API (29-09)
A6: 2 | B6: Aplicación móvil para inversionistas | C6: E8 | D6: HU-16 | E6: R2 | F6: Implementado | G6: Front-end terminado el 03-10-2026; la conexión con la API se hace en el Sprint 6 (Android Studio)
A7: 3 | B7: Backend API REST | C7: E9 | D7: HU-04 | E7: R2 | F7: En desarrollo | G7: FastAPI: autenticación, propiedades, vistas, favoritos, alertas y comunas
A8: 4 | B8: Módulo de autenticación y 2FA | C8: E1 | D8: HU-01, 09, 12 | E8: R1 | F8: Implementado | G8: Registro e inicio de sesión con JWT y bcrypt; /auth/me (29-09). La verificación en dos pasos (HU-09) está en el backlog, sin sprint
A9: 5 | B9: Gestión de usuarios y roles | C9: E1 | D9: HU-17, 22 | E9: R1 | F9: Implementado | G9: Roles 1, 2 y 3; rutas y menú del administrador solo para su rol (29-09)
A10: 6 | B10: Módulo de propiedades | C10: E2 | D10: HU-02, 06 | E10: R1 | F10: En desarrollo | G10: CRUD en la API; DEF-01 y DEF-03 corregidos (01-10 y 04-10), falta la re-prueba
A11: 7 | B11: Módulo de geografía | C11: E6 | D11: HU-15 | E11: R1 | F11: Implementado | G11: Tabla de comunas y endpoint /comunas
A12: 8 | B12: Motor de reglas y semáforo | C12: E3 | D12: HU-03 | E12: R1 | F12: Implementado | G12: calculate_score() en PL/pgSQL; umbrales corregidos (28-09); reglas probadas (30-09)
A13: 9 | B13: Administrador del motor de reglas | C13: E3 | D13: HU-11 | E13: R3 | F13: Descartada | G13: Pantallas diseñadas; historia descartada el 29-09: el administrador no configura las reglas
A14: 10 | B14: Trazabilidad de evaluaciones | C14: E3 | D14: HU-05 | E14: R1 | F14: Implementado | G14: property_evaluations y evaluation_details
A15: 11 | B15: Módulo de propiedades guardadas | C15: E4 | D15: HU-07 | E15: R1 | F15: Implementado | G15: La web usa GET, POST y DELETE /favoritos (29-09)
A16: 12 | B16: Módulo de cobertura | C16: E6 | D16: HU-15 | E16: R1 | F16: Diseñado | G16: coverage_zones en el modelo de datos
... A23: 19 | B23: Despliegue de la solución | C23: E9 | D23: HU-20 | E23: R2 | F23: Planificado | G23: Arquitectura de despliegue en Railway

Sheet G7 Story Map
A1: User Story Mapping
A4: Release | B4: Acceder | C4: Buscar remates | D4: Evaluar una propiedad | E4: Hacer seguimiento | F4: Administrar datos | G4: Operar y analizar
A5: R1 · MVP web Sprints 4 y 5 al 13-10-2026 | B5: HU-01 Registrarse e iniciar sesión | C5: HU-02 Ver el catálogo | D5: HU-03 Semáforo automático | E5: HU-07 Guardar propiedades | F5: HU-08 Fotos y descripción | G5: HU-17 Panel del analista
B6: HU-12 Recuperar contraseña | C6: HU-06 Filtros | D6: HU-05 Justificación por factor | F6: HU-10 Carga automática de remates | G6: HU-18 Anuncios y opiniones
C7: HU-15 Mapa por comuna | F7: HU-23 Vistas y guardados por publicación
A8: R2 · Conexión, pruebas y cierre Sprints 6 a 7 al 04-11-2026 | C8: HU-16 App móvil | E8: HU-13 Alertas por filtros | G8: HU-04 API documentada /api/v1
E9: HU-14 Historial de alertas | G9: HU-19 Pruebas automatizadas
G10: HU-20 Despliegue de demostración
G11: HU-21 Validación con usuarios
A12: R3 · Backlog sin sprint asignado | B12: HU-09 2FA del administrador | D12: HU-11 Reglas e índice comunal (descartada)
B13: HU-22 Seguridad y auditoría
A14: Verde: historia hecha. Crema: en curso. Blanco: por hacer.

Sheet G8 Releases
A1: Release Planning
A4: Release | B4: Nombre | C4: Sprints | D4: Término | E4: Qué puede hacer el usuario al final | F4: Historias | G4: Puntos | H4: Entregables (N.º)
A5: R1 | B5: MVP web | C5: 4 y 5 | D5: 46308 | E5: Registrarse, ver el catálogo con remates reales de rematesinmobiliarios.cl, filtrar, abrir el detalle con el semáforo explicado, guardar propiedades y recibir anuncios; el administrador edita fotos y descripción y ve quién vio cada publicación; el analista ve las métricas. | F5: HU-01, HU-02, HU-03, HU-05, HU-06, HU-07, HU-08, HU-10, HU-12, HU-15, HU-17, HU-18, HU-23 | G5: =SUMIF('G4 Product Backlog'!$M$5:$M$27,A5,'G4 Product Backlog'!$J$5:$J$27) -> 73 | H5: 1, 4, 5, 6, 7, 8, 10, 11, 12, 14, 15, 16
A6: R2 | B6: Conexión, pruebas y cierre | C6: 6 a 7 | D6: 46330 | E6: Usar la app móvil conectada a la API, recibir alertas por filtros y ver su historial, entrar a la demostración en la nube y participar en la validación con usuarios. | F6: HU-04, HU-13, HU-14, HU-16, HU-19, HU-20, HU-21 | G6: =SUMIF('G4 Product Backlog'!$M$5:$M$27,A6,'G4 Product Backlog'!$J$5:$J$27) -> 45 | H6: 2, 3, 13, 18, 19
A7: R3 | B7: Backlog sin sprint asignado | C7: — | D7: — | E7: Historias que aún no tienen tareas en ningún sprint: verificación en dos pasos del administrador (HU-09) y seguridad y auditoría (HU-22). El equipo decide si entran antes de la entrega. La configuración de reglas (HU-11) se descartó. | F7: HU-09, HU-11, HU-22 | G7: =SUMIF('G4 Product Backlog'!$M$5:$M$27,A7,'G4 Product Backlog'!$J$5:$J$27) -> 18 | H7: 9, 17

Sheet H1 Sprints
A1: Calendario de sprints
A2: Un ciclo por sprint. Los sprints se cruzan en fechas porque los tres integrantes trabajan en paralelo. El proyecto comenzó el 20-08-2026; el Sprint 7 termina el 04-11 y la entrega es el 05-11-2026.
A4: Sprint | B4: Inicio | C4: Término | D4: Sprint Goal | E4: Release | F4: Puntos | G4: Tareas | H4: Hechas | I4: Estado
A5: 1 | B5: 46261 | C5: =B5+28 -> 46289 | D5: Documentación fase 1: definir el problema, la idea, los requisitos y la evaluación económica | E5: — | F5: =SUMIF('G4 Product Backlog'!$L$5:$L$27,A5,'G4 Product Backlog'!$J$5:$J$27) -> 0 | G5: =COUNTA('H3 Sprint 1'!B15:B20) -> 6 | H5: =COUNTIF('H3 Sprint 1'!H15:H20,"Hecho") -> 6 | I5: Terminado
A6: 2 | B6: 46272 | C6: =B6+26 -> 46298 | D6: Front-end móvil: construir las pantallas de la aplicación del inversionista | E6: — | F6: =SUMIF('G4 Product Backlog'!$L$5:$L$27,A6,'G4 Product Backlog'!$J$5:$J$27) -> 0 | G6: =COUNTA('H4 Sprint 2'!B15:B21) -> 7 | H6: =COUNTIF('H4 Sprint 2'!H15:H21,"Hecho") -> 7 | I6: Terminado
A7: 3 | B7: 46289 | C7: =B7+19 -> 46308 | D7: Complemento: prototipo, procesos AS-IS y TO-BE, vistas 4+1, modelo de datos y secciones complementarias del informe | E7: — | F7: =SUMIF('G4 Product Backlog'!$L$5:$L$27,A7,'G4 Product Backlog'!$J$5:$J$27) -> 0 | G7: =COUNTA('H5 Sprint 3'!B15:B24) -> 10 | H7: =COUNTIF('H5 Sprint 3'!H15:H24,"Hecho") -> 10 | I7: En curso
A8: 4 | B8: 46272 | C8: =B8+26 -> 46298 | D8: Backend: base de datos, API, base en la nube conectada con la página web y carga automática de remates | E8: R1 | F8: =SUMIF('G4 Product Backlog'!$L$5:$L$27,A8,'G4 Product Backlog'!$J$5:$J$27) -> 39 | G8: =COUNTA('H12 Sprint 4'!B15:B26) -> 12 | H8: =COUNTIF('H12 Sprint 4'!H15:H26,"Hecho") -> 12 | I8: Terminado
A9: 5 | B9: 46289 | C9: =B9+19 -> 46308 | D9: Front-end web: pantallas del inversionista, el administrador y el analista | E9: R1 | F9: =SUMIF('G4 Product Backlog'!$L$5:$L$27,A9,'G4 Product Backlog'!$J$5:$J$27) -> 34 | G9: =COUNTA('H13 Sprint 5'!B15:B28) -> 14 | H9: =COUNTIF('H13 Sprint 5'!H15:H28,"Hecho") -> 12 | I9: En curso
A10: 6 | B10: 46299 | C10: =B10+20 -> 46319 | D10: Conexión: conectar la app móvil (Android Studio) y la web con la API, y dejar la demostración en la nube | E10: R2 | F10: =SUMIF('G4 Product Backlog'!$L$5:$L$27,A10,'G4 Product Backlog'!$J$5:$J$27) -> 40 | G10: =COUNTA('H14 Sprint 6'!B15:B23) -> 9 | H10: =COUNTIF('H14 Sprint 6'!H15:H23,"Hecho") -> 5 | I10: En curso
A11: 7 | B11: 46320 | C11: =B11+10 -> 46330 | D11: Documentación fase 2 y cierre: pruebas, informe final y demostración | E11: R2 | F11: =SUMIF('G4 Product Backlog'!$L$5:$L$27,A11,'G4 Product Backlog'!$J$5:$J$27) -> 5 | G11: =COUNTA('H15 Sprint 7'!B15:B22) -> 8 | H11: =COUNTIF('H15 Sprint 7'!H15:H22,"Hecho") -> 1 | I11: Planificado
A14: Horas estimadas por integrante y sprint
D15: Integrante | E15: S1 | F15: S2 | G15: S3 | H15: S4 | I15: S5 | J15: S6 | K15: S7 | L15: Total | M15: Disponibles | N15: Uso
D16: Matías Negrete | E16: =SUMIF('H3 Sprint 1'!$D$15:$D$20,$D16,'H3 Sprint 1'!$E$15:$E$20) -> 34 | F16: =SUMIF('H4 Sprint 2'!$D$15:$D$21,$D16,'H4 Sprint 2'!$E$15:$E$21) -> 0 | G16: =SUMIF('H5 Sprint 3'!$D$15:$D$24,$D16,'H5 Sprint 3'!$E$15:$E$24) -> 28 | H16: =SUMIF('H12 Sprint 4'!$D$15:$D$26,$D16,'H12 Sprint 4'!$E$15:$E$26) -> 5 | I16: =SUMIF('H13 Sprint 5'!$D$15:$D$28,$D16,'H13 Sprint 5'!$E$15:$E$28) -> 0 | J16: =SUMIF('H14 Sprint 6'!$D$15:$D$23,$D16,'H14 Sprint 6'!$E$15:$E$23) -> 0 | K16: =SUMIF('H15 Sprint 7'!$D$15:$D$22,$D16,'H15 Sprint 7'!$E$15:$E$22) -> 14 | L16: =SUM(E16:K16) -> 81 | M16: ='G1 Squad'!$D$5*11 -> 110 | N16: =L16/M16 -> 0.73636364
D17: José Pizarro | E17: =SUMIF('H3 Sprint 1'!$D$15:$D$20,$D17,'H3 Sprint 1'!$E$15:$E$20) -> 0 | F17: =SUMIF('H4 Sprint 2'!$D$15:$D$21,$D17,'H4 Sprint 2'!$E$15:$E$21) -> 0 | G17: =SUMIF('H5 Sprint 3'!$D$15:$D$24,$D17,'H5 Sprint 3'!$E$15:$E$24) -> 0 | H17: =SUMIF('H12 Sprint 4'!$D$15:$D$26,$D17,'H12 Sprint 4'!$E$15:$E$26) -> 29 | I17: =SUMIF('H13 Sprint 5'!$D$15:$D$28,$D17,'H13 Sprint 5'!$E$15:$E$28) -> 28 | J17: =SUMIF('H14 Sprint 6'!$D$15:$D$23,$D17,'H14 Sprint 6'!$E$15:$E$23) -> 17 | K17: =SUMIF('H15 Sprint 7'!$D$15:$D$22,$D17,'H15 Sprint 7'!$E$15:$E$22) -> 9 | L17: =SUM(E17:K17) -> 83 | M17: ='G1 Squad'!$D$5*11 -> 110 | N17: =L17/M17 -> 0.75454545
D18: Basthian Bascuñan | E18: =SUMIF('H3 Sprint 1'!$D$15:$D$20,$D18,'H3 Sprint 1'!$E$15:$E$20) -> 0 | F18: =SUMIF('H4 Sprint 2'!$D$15:$D$21,$D18,'H4 Sprint 2'!$E$15:$E$21) -> 36 | G18: =SUMIF('H5 Sprint 3'!$D$15:$D$24,$D18,'H5 Sprint 3'!$E$15:$E$24) -> 0 | H18: =SUMIF('H12 Sprint 4'!$D$15:$D$26,$D18,'H12 Sprint 4'!$E$15:$E$26) -> 0 | I18: =SUMIF('H13 Sprint 5'!$D$15:$D$28,$D18,'H13 Sprint 5'!$E$15:$E$28) -> 11 | J18: =SUMIF('H14 Sprint 6'!$D$15:$D$23,$D18,'H14 Sprint 6'!$E$15:$E$23) -> 19 | K18: =SUMIF('H15 Sprint 7'!$D$15:$D$22,$D18,'H15 Sprint 7'!$E$15:$E$22) -> 14 | L18: =SUM(E18:K18) -> 80 | M18: ='G1 Squad'!$D$5*11 -> 110 | N18: =L18/M18 -> 0.72727273
D19: Total del sprint | E19: =SUM(E16:E18) -> 34 | F19: =SUM(F16:F18) -> 36 | G19: =SUM(G16:G18) -> 28 | H19: =SUM(H16:H18) -> 34 | I19: =SUM(I16:I18) -> 39 | J19: =SUM(J16:J18) -> 36 | K19: =SUM(K16:K18) -> 37 | L19: =SUM(E19:K19) -> 244 | M19: =SUM(M16:M18) -> 330 | N19: =L19/M19 -> 0.73939394
D20: Capacidad del sprint | E20: ='H3 Sprint 1'!$C$8 -> 41 | F20: ='H4 Sprint 2'!$C$8 -> 39 | G20: ='H5 Sprint 3'!$C$8 -> 29 | H20: ='H12 Sprint 4'!$C$8 -> 77 | I20: ='H13 Sprint 5'!$C$8 -> 57 | J20: ='H14 Sprint 6'!$C$8 -> 60 | K20: ='H15 Sprint 7'!$C$8 -> 47
D22: Disponibles: 10 horas semanales durante las 11 semanas del proyecto (20-08 al 05-11-2026). La capacidad de cada sprint cuenta solo a quienes trabajan en él; como los sprints se cruzan, la carga real de cada persona se revisa en la fila de su nombre.

Sheet H2 Definition of Done
A1: Definition of Done
A4: N.º | B4: Criterio | C4: Aplica a | D4: Cómo se verifica
A5: 1 | B5: El código está en GitHub y otro integrante revisó y aprobó el pull request | C5: Tarea | D5: Pull request aprobado
A6: 2 | B6: Cumple sus criterios de aceptación y se puede demostrar | C6: Historia | D6: Escenarios de la historia ejecutados
A7: 3 | B7: Tiene pruebas automatizadas del caso normal y de al menos un caso de error, y pasan | C7: Historia | D7: pytest / Playwright en verde
A8: 4 | B8: No deja defectos críticos ni altos abiertos | C8: Historia | D8: Registro de defectos
A9: 5 | B9: Funciona con los datos de prueba en el ambiente de pruebas | C9: Historia | D9: Ejecución en la base de prueba
A10: 6 | B10: La documentación quedó al día (OpenAPI, README o informe) | C10: Tarea | D10: Revisión en la Review
A11: 7 | B11: Respeta los criterios de seguridad y accesibilidad cuando aplican | C11: Historia | D11: Checklist de la sección E
A12: 8 | B12: El Product Owner la aceptó en la Sprint Review | C12: Incremento | D12: Validación A/R en la planilla

Sheet H3 Sprint 1
A1: Sprint 1 · Documentación fase 1 · 27-08 al 24-09-2026
A2: Ciclo: Documentación fase 1 · 29 días · trabaja: Matías Negrete · plan del 04-10-2026 (un ciclo por sprint; los sprints se cruzan en fechas)
B3: Sprint Goal | C3: Documentación fase 1: definir el problema, la idea, los requisitos y la evaluación económica
B4: Inicio | C4: 46261
B5: Término | C5: =IF(C4="","",C4+28) -> 46289
B6: Asistentes al Sprint Planning
B7: Historias comprometidas | C7: Sin historias de usuario: sprint de definición y documentación
B8: Capacidad del sprint (h) | C8: =ROUND(1*10*29/7,0) -> 41
B9: Horas estimadas | C9: =SUM(E15:E20) -> 34
B10: Tareas comprometidas al inicio | C10: =COUNTIF(G15:G20,C4) -> 6
B11: Fecha de corte | C11: 46289
A13: Sprint Backlog | J13: Avance día a día (✔ = tarea terminada) | AM13: PO
A14: N.º | B14: Tarea | C14: Relación | D14: Responsable | E14: Horas est. | F14: Horas reales | G14: Alta | H14: Estado | I14: Término | J14: =IF($C$4="","",$C$4+0) -> 46261 | K14: =IF($C$4="","",$C$4+1) -> 46262 | L14: =IF($C$4="","",$C$4+2) -> 46263 | M14: =IF($C$4="","",$C$4+3) -> 46264 | N14: =IF($C$4="","",$C$4+4) -> 46265 | O14: =IF($C$4="","",$C$4+5) -> 46266 | P14: =IF($C$4="","",$C$4+6) -> 46267 | Q14: =IF($C$4="","",$C$4+7) -> 46268 | R14: =IF($C$4="","",$C$4+8) -> 46269 | S14: =IF($C$4="","",$C$4+9) -> 46270 | T14: =IF($C$4="","",$C$4+10) -> 46271 | U14: =IF($C$4="","",$C$4+11) -> 46272 | V14: =IF($C$4="","",$C$4+12) -> 46273 | W14: =IF($C$4="","",$C$4+13) -> 46274 | X14: =IF($C$4="","",$C$4+14) -> 46275 | Y14: =IF($C$4="","",$C$4+15) -> 46276 | Z14: =IF($C$4="","",$C$4+16) -> 46277 | AA14: =IF($C$4="","",$C$4+17) -> 46278 | AB14: =IF($C$4="","",$C$4+18) -> 46279 | AC14: =IF($C$4="","",$C$4+19) -> 46280 | AD14: =IF($C$4="","",$C$4+20) -> 46281 | AE14: =IF($C$4="","",$C$4+21) -> 46282 | AF14: =IF($C$4="","",$C$4+22) -> 46283 | AG14: =IF($C$4="","",$C$4+23) -> 46284 | AH14: =IF($C$4="","",$C$4+24) -> 46285 | AI14: =IF($C$4="","",$C$4+25) -> 46286 | AJ14: =IF($C$4="","",$C$4+26) -> 46287 | AK14: =IF($C$4="","",$C$4+27) -> 46288 | AL14: =IF($C$4="","",$C$4+28) -> 46289 | AM14: PO (A/R)
A15: 1 | B15: Informe inicial: problema, idea de negocio y objetivos | C15: Documentación | D15: Matías Negrete | E15: 6 | G15: 46261 | H15: Hecho | I15: 46261 | J15: =IF($I15=J$14,"✔","") -> ✔ | K15: =IF($I15=K$14,"✔","") | L15: =IF($I15=L$14,"✔","") | M15: =IF($I15=M$14,"✔","") | N15: =IF($I15=N$14,"✔","") | O15: =IF($I15=O$14,"✔","") | P15: =IF($I15=P$14,"✔","") | Q15: =IF($I15=Q$14,"✔","") | ... AL15: =IF($I15=AL$14,"✔","") | AM15: A
A16: 2 | B16: Plan A y mapa mental | C16: Documentación | D16: Matías Negrete | E16: 4 | G16: 46261 | H16: Hecho | I16: 46263 | J16: =IF($I16=J$14,"✔","") | K16: =IF($I16=K$14,"✔","") | L16: =IF($I16=L$14,"✔","") -> ✔ | M16: =IF($I16=M$14,"✔","") | N16: =IF($I16=N$14,"✔","") | O16: =IF($I16=O$14,"✔","") | P16: =IF($I16=P$14,"✔","") | Q16: =IF($I16=Q$14,"✔","") | ... AL16: =IF($I16=AL$14,"✔","") | AM16: A
A17: 3 | B17: Mejora general del informe: actores, visión y alcance | C17: Documentación | D17: Matías Negrete | E17: 6 | G17: 46261 | H17: Hecho | I17: 46265 | J17: =IF($I17=J$14,"✔","") | K17: =IF($I17=K$14,"✔","") | L17: =IF($I17=L$14,"✔","") | M17: =IF($I17=M$14,"✔","") | N17: =IF($I17=N$14,"✔","") -> ✔ | O17: =IF($I17=O$14,"✔","") | P17: =IF($I17=P$14,"✔","") | Q17: =IF($I17=Q$14,"✔","") | ... AL17: =IF($I17=AL$14,"✔","") | AM17: A
A18: 4 | B18: Requisitos y justificación de las decisiones (secciones A, B, C y D) | C18: Documentación | D18: Matías Negrete | E18: 8 | G18: 46261 | H18: Hecho | I18: 46287 | J18: =IF($I18=J$14,"✔","") | K18: =IF($I18=K$14,"✔","") | L18: =IF($I18=L$14,"✔","") | M18: =IF($I18=M$14,"✔","") | N18: =IF($I18=N$14,"✔","") | O18: =IF($I18=O$14,"✔","") | P18: =IF($I18=P$14,"✔","") | Q18: =IF($I18=Q$14,"✔","") | ... AL18: =IF($I18=AL$14,"✔","") | AM18: A
A19: 5 | B19: Flujo de caja corregido: VAN, TIR y punto de equilibrio | C19: Evaluación económica | D19: Matías Negrete | E19: 5 | G19: 46261 | H19: Hecho | I19: 46288 | J19: =IF($I19=J$14,"✔","") | K19: =IF($I19=K$14,"✔","") | L19: =IF($I19=L$14,"✔","") | M19: =IF($I19=M$14,"✔","") | N19: =IF($I19=N$14,"✔","") | O19: =IF($I19=O$14,"✔","") | P19: =IF($I19=P$14,"✔","") | Q19: =IF($I19=Q$14,"✔","") | ... AL19: =IF($I19=AL$14,"✔","") | AM19: A
A20: 6 | B20: Respaldo de mercado: oferta de remates, morosidad y competencia | C20: Evaluación económica | D20: Matías Negrete | E20: 5 | G20: 46261 | H20: Hecho | I20: 46289 | J20: =IF($I20=J$14,"✔","") | K20: =IF($I20=K$14,"✔","") | L20: =IF($I20=L$14,"✔","") | M20: =IF($I20=M$14,"✔","") | N20: =IF($I20=N$14,"✔","") | O20: =IF($I20=O$14,"✔","") | P20: =IF($I20=P$14,"✔","") | Q20: =IF($I20=Q$14,"✔","") | ... AL20: =IF($I20=AL$14,"✔","") -> ✔ | AM20: A
B21: Total | E21: =SUM(E15:E20) -> 34 | F21: =SUM(F15:F20) -> 0 | H21: =COUNTIF(H15:H20,"Hecho")&" hechas" -> 6 hechas
A23: Burndown del sprint
A24: Día | B24: Fecha | C24: Ideal | D24: Pendientes
A25: 0 | B25: inicio | C25: =IF($C$10=0,"",ROUND($C$10-$C$10*A25/29,1)) -> 6 | D25: 6
A26: 1 | B26: 27-08 | C26: =IF($C$10=0,"",ROUND($C$10-$C$10*A26/29,1)) -> 5.8 | D26: 5
A27: 2 | B27: 28-08 | C27: =IF($C$10=0,"",ROUND($C$10-$C$10*A27/29,1)) -> 5.6 | D27: 5
A28: 3 | B28: 29-08 | C28: =IF($C$10=0,"",ROUND($C$10-$C$10*A28/29,1)) -> 5.4 | D28: 4
A29: 4 | B29: 30-08 | C29: =IF($C$10=0,"",ROUND($C$10-$C$10*A29/29,1)) -> 5.2 | D29: 4
A30: 5 | B30: 31-08 | C30: =IF($C$10=0,"",ROUND($C$10-$C$10*A30/29,1)) -> 5 | D30: 3
A31: 6 | B31: 01-09 | C31: =IF($C$10=0,"",ROUND($C$10-$C$10*A31/29,1)) -> 4.8 | D31: 3
A32: 7 | B32: 02-09 | C32: =IF($C$10=0,"",ROUND($C$10-$C$10*A32/29,1)) -> 4.6 | D32: 3
A33: 8 | B33: 03-09 | C33: =IF($C$10=0,"",ROUND($C$10-$C$10*A33/29,1)) -> 4.3 | D33: 3
A34: 9 | B34: 04-09 | C34: =IF($C$10=0,"",ROUND($C$10-$C$10*A34/29,1)) -> 4.1 | D34: 3
A35: 10 | B35: 05-09 | C35: =IF($C$10=0,"",ROUND($C$10-$C$10*A35/29,1)) -> 3.9 | D35: 3
A36: 11 | B36: 06-09 | C36: =IF($C$10=0,"",ROUND($C$10-$C$10*A36/29,1)) -> 3.7 | D36: 3
... A54: 29 | B54: 24-09 | C54: =IF($C$10=0,"",ROUND($C$10-$C$10*A54/29,1)) -> 0 | D54: 0

Sheet H4 Sprint 2
A1: Sprint 2 · Front-end móvil · 07-09 al 03-10-2026
A2: Ciclo: Front-end móvil · 27 días · trabaja: Basthian Bascuñan · plan del 04-10-2026 (un ciclo por sprint; los sprints se cruzan en fechas)
B3: Sprint Goal | C3: Front-end móvil: construir las pantallas de la aplicación del inversionista
B4: Inicio | C4: 46272
B5: Término | C5: =IF(C4="","",C4+26) -> 46298
B6: Asistentes al Sprint Planning
B7: Historias comprometidas | C7: Pantallas de HU-16; la historia se cierra en el Sprint 6, cuando la app se conecta con la API
B8: Capacidad del sprint (h) | C8: =ROUND(1*10*27/7,0) -> 39
B9: Horas estimadas | C9: =SUM(E15:E21) -> 36
B10: Tareas comprometidas al inicio | C10: =COUNTIF(G15:G21,C4) -> 7
B11: Fecha de corte | C11: 46298
A13: Sprint Backlog | J13: Avance día a día (✔ = tarea terminada) | AK13: PO
A14: N.º | B14: Tarea | C14: Relación | D14: Responsable | E14: Horas est. | F14: Horas reales | G14: Alta | H14: Estado | I14: Término | J14: =IF($C$4="","",$C$4+0) -> 46272 | K14: =IF($C$4="","",$C$4+1) -> 46273 | L14: =IF($C$4="","",$C$4+2) -> 46274 | M14: =IF($C$4="","",$C$4+3) -> 46275 | N14: =IF($C$4="","",$C$4+4) -> 46276 | O14: =IF($C$4="","",$C$4+5) -> 46277 | P14: =IF($C$4="","",$C$4+6) -> 46278 | Q14: =IF($C$4="","",$C$4+7) -> 46279 | R14: =IF($C$4="","",$C$4+8) -> 46280 | S14: =IF($C$4="","",$C$4+9) -> 46281 | T14: =IF($C$4="","",$C$4+10) -> 46282 | U14: =IF($C$4="","",$C$4+11) -> 46283 | V14: =IF($C$4="","",$C$4+12) -> 46284 | W14: =IF($C$4="","",$C$4+13) -> 46285 | X14: =IF($C$4="","",$C$4+14) -> 46286 | Y14: =IF($C$4="","",$C$4+15) -> 46287 | Z14: =IF($C$4="","",$C$4+16) -> 46288 | AA14: =IF($C$4="","",$C$4+17) -> 46289 | AB14: =IF($C$4="","",$C$4+18) -> 46290 | AC14: =IF($C$4="","",$C$4+19) -> 46291 | AD14: =IF($C$4="","",$C$4+20) -> 46292 | AE14: =IF($C$4="","",$C$4+21) -> 46293 | AF14: =IF($C$4="","",$C$4+22) -> 46294 | AG14: =IF($C$4="","",$C$4+23) -> 46295 | AH14: =IF($C$4="","",$C$4+24) -> 46296 | AI14: =IF($C$4="","",$C$4+25) -> 46297 | AJ14: =IF($C$4="","",$C$4+26) -> 46298 | AK14: PO (A/R)
A15: 1 | B15: App: estructura del proyecto, navegación y estilos del prototipo | C15: HU-16 | D15: Basthian Bascuñan | E15: 5 | G15: 46272 | H15: Hecho | I15: 46277 | J15: =IF($I15=J$14,"✔","") | K15: =IF($I15=K$14,"✔","") | L15: =IF($I15=L$14,"✔","") | M15: =IF($I15=M$14,"✔","") | N15: =IF($I15=N$14,"✔","") | O15: =IF($I15=O$14,"✔","") -> ✔ | P15: =IF($I15=P$14,"✔","") | Q15: =IF($I15=Q$14,"✔","") | ... AJ15: =IF($I15=AJ$14,"✔","") | AK15: A
A16: 2 | B16: App: pantallas de inicio de sesión y registro | C16: HU-16 · HU-01 | D16: Basthian Bascuñan | E16: 5 | G16: 46272 | H16: Hecho | I16: 46282 | J16: =IF($I16=J$14,"✔","") | K16: =IF($I16=K$14,"✔","") | L16: =IF($I16=L$14,"✔","") | M16: =IF($I16=M$14,"✔","") | N16: =IF($I16=N$14,"✔","") | O16: =IF($I16=O$14,"✔","") | P16: =IF($I16=P$14,"✔","") | Q16: =IF($I16=Q$14,"✔","") | ... AJ16: =IF($I16=AJ$14,"✔","") | AK16: A
A17: 3 | B17: App: pantalla de inicio | C17: HU-16 | D17: Basthian Bascuñan | E17: 4 | G17: 46272 | H17: Hecho | I17: 46286 | J17: =IF($I17=J$14,"✔","") | K17: =IF($I17=K$14,"✔","") | L17: =IF($I17=L$14,"✔","") | M17: =IF($I17=M$14,"✔","") | N17: =IF($I17=N$14,"✔","") | O17: =IF($I17=O$14,"✔","") | P17: =IF($I17=P$14,"✔","") | Q17: =IF($I17=Q$14,"✔","") | ... AJ17: =IF($I17=AJ$14,"✔","") | AK17: A
A18: 4 | B18: App: pantallas de guardados y notificaciones | C18: HU-16 · HU-07 | D18: Basthian Bascuñan | E18: 6 | G18: 46272 | H18: Hecho | I18: 46292 | J18: =IF($I18=J$14,"✔","") | K18: =IF($I18=K$14,"✔","") | L18: =IF($I18=L$14,"✔","") | M18: =IF($I18=M$14,"✔","") | N18: =IF($I18=N$14,"✔","") | O18: =IF($I18=O$14,"✔","") | P18: =IF($I18=P$14,"✔","") | Q18: =IF($I18=Q$14,"✔","") | ... AJ18: =IF($I18=AJ$14,"✔","") | AK18: A
A19: 5 | B19: App: pantalla de perfil | C19: HU-16 | D19: Basthian Bascuñan | E19: 4 | G19: 46272 | H19: Hecho | I19: 46295 | J19: =IF($I19=J$14,"✔","") | K19: =IF($I19=K$14,"✔","") | L19: =IF($I19=L$14,"✔","") | M19: =IF($I19=M$14,"✔","") | N19: =IF($I19=N$14,"✔","") | O19: =IF($I19=O$14,"✔","") | P19: =IF($I19=P$14,"✔","") | Q19: =IF($I19=Q$14,"✔","") | ... AJ19: =IF($I19=AJ$14,"✔","") | AK19: A
A20: 6 | B20: App: pantallas de catálogo y detalle con semáforo | C20: HU-16 · HU-02 | D20: Basthian Bascuñan | E20: 8 | F20: 7 | G20: 46272 | H20: Hecho | I20: 46298 | J20: =IF($I20=J$14,"✔","") | K20: =IF($I20=K$14,"✔","") | L20: =IF($I20=L$14,"✔","") | M20: =IF($I20=M$14,"✔","") | N20: =IF($I20=N$14,"✔","") | O20: =IF($I20=O$14,"✔","") | P20: =IF($I20=P$14,"✔","") | Q20: =IF($I20=Q$14,"✔","") | ... AJ20: =IF($I20=AJ$14,"✔","") -> ✔ | AK20: A
A21: 7 | B21: App: revisión del front-end completo en el emulador | C21: HU-16 | D21: Basthian Bascuñan | E21: 4 | G21: 46272 | H21: Hecho | I21: 46298 | J21: =IF($I21=J$14,"✔","") | K21: =IF($I21=K$14,"✔","") | L21: =IF($I21=L$14,"✔","") | M21: =IF($I21=M$14,"✔","") | N21: =IF($I21=N$14,"✔","") | O21: =IF($I21=O$14,"✔","") | P21: =IF($I21=P$14,"✔","") | Q21: =IF($I21=Q$14,"✔","") | ... AJ21: =IF($I21=AJ$14,"✔","") -> ✔ | AK21: A
B22: Total | E22: =SUM(E15:E21) -> 36 | F22: =SUM(F15:F21) -> 7 | H22: =COUNTIF(H15:H21,"Hecho")&" hechas" -> 7 hechas
A24: Burndown del sprint
A25: Día | B25: Fecha | C25: Ideal | D25: Pendientes
A26: 0 | B26: inicio | C26: =IF($C$10=0,"",ROUND($C$10-$C$10*A26/27,1)) -> 7 | D26: 7
A27: 1 | B27: 07-09 | C27: =IF($C$10=0,"",ROUND($C$10-$C$10*A27/27,1)) -> 6.7 | D27: 7
A28: 2 | B28: 08-09 | C28: =IF($C$10=0,"",ROUND($C$10-$C$10*A28/27,1)) -> 6.5 | D28: 7
A29: 3 | B29: 09-09 | C29: =IF($C$10=0,"",ROUND($C$10-$C$10*A29/27,1)) -> 6.2 | D29: 7
A30: 4 | B30: 10-09 | C30: =IF($C$10=0,"",ROUND($C$10-$C$10*A30/27,1)) -> 6 | D30: 7
A31: 5 | B31: 11-09 | C31: =IF($C$10=0,"",ROUND($C$10-$C$10*A31/27,1)) -> 5.7 | D31: 7
A32: 6 | B32: 12-09 | C32: =IF($C$10=0,"",ROUND($C$10-$C$10*A32/27,1)) -> 5.4 | D32: 6
A33: 7 | B33: 13-09 | C33: =IF($C$10=0,"",ROUND($C$10-$C$10*A33/27,1)) -> 5.2 | D33: 6
A34: 8 | B34: 14-09 | C34: =IF($C$10=0,"",ROUND($C$10-$C$10*A34/27,1)) -> 4.9 | D34: 6
A35: 9 | B35: 15-09 | C35: =IF($C$10=0,"",ROUND($C$10-$C$10*A35/27,1)) -> 4.7 | D35: 6
A36: 10 | B36: 16-09 | C36: =IF($C$10=0,"",ROUND($C$10-$C$10*A36/27,1)) -> 4.4 | D36: 6
A37: 11 | B37: 17-09 | C37: =IF($C$10=0,"",ROUND($C$10-$C$10*A37/27,1)) -> 4.1 | D37: 5
... A53: 27 | B53: 03-10 | C53: =IF($C$10=0,"",ROUND($C$10-$C$10*A53/27,1)) -> 0 | D53: 0

Sheet H5 Sprint 3
A1: Sprint 3 · Complemento · 24-09 al 13-10-2026
B3: Sprint Goal | C3: Complemento: prototipo, procesos AS-IS y TO-BE, vistas 4+1, modelo de datos y secciones complementarias del informe
B4: Inicio | C4: 46289
B5: Término | C5: =IF(C4="","",C4+19) -> 46308
B6: Asistentes al Sprint Planning
B7: Historias comprometidas | C7: Sin historias de usuario: sprint de diseño y documentación
B8: Capacidad del sprint (h) | C8: =ROUND(1*10*20/7,0) -> 29
B9: Horas estimadas | C9: =SUM(E15:E24) -> 28
B10: Tareas comprometidas al inicio | C10: =COUNTIF(G15:G24,C4) -> 8
B11: Fecha de corte | C11: 46299
A13: Sprint Backlog | J13: Avance día a día (✔ = tarea terminada) | AD13: PO
A14: N.º | B14: Tarea | C14: Relación | D14: Responsable | E14: Horas est. | F14: Horas reales | G14: Alta | H14: Estado | I14: Término | J14: =IF($C$4="","",$C$4+0) -> 46289 | K14: =IF($C$4="","",$C$4+1) -> 46290 | L14: =IF($C$4="","",$C$4+2) -> 46291 | M14: =IF($C$4="","",$C$4+3) -> 46292 | N14: =IF($C$4="","",$C$4+4) -> 46293 | O14: =IF($C$4="","",$C$4+5) -> 46294 | P14: =IF($C$4="","",$C$4+6) -> 46295 | Q14: =IF($C$4="","",$C$4+7) -> 46296 | R14: =IF($C$4="","",$C$4+8) -> 46297 | S14: =IF($C$4="","",$C$4+9) -> 46298 | T14: =IF($C$4="","",$C$4+10) -> 46299 | U14: =IF($C$4="","",$C$4+11) -> 46300 | V14: =IF($C$4="","",$C$4+12) -> 46301 | W14: =IF($C$4="","",$C$4+13) -> 46302 | X14: =IF($C$4="","",$C$4+14) -> 46303 | Y14: =IF($C$4="","",$C$4+15) -> 46304 | Z14: =IF($C$4="","",$C$4+16) -> 46305 | AA14: =IF($C$4="","",$C$4+17) -> 46306 | AB14: =IF($C$4="","",$C$4+18) -> 46307 | AC14: =IF($C$4="","",$C$4+19) -> 46308 | AD14: PO (A/R)
A15: 1 | B15: Prototipo de la app pública (11 pantallas) | C15: Diseño | D15: Matías Negrete | E15: 4 | G15: 46289 | H15: Hecho | I15: 46290 | J15: =IF($I15=J$14,"✔","") | K15: =IF($I15=K$14,"✔","") -> ✔ | L15: =IF($I15=L$14,"✔","") | M15: =IF($I15=M$14,"✔","") | N15: =IF($I15=N$14,"✔","") | O15: =IF($I15=O$14,"✔","") | P15: =IF($I15=P$14,"✔","") | Q15: =IF($I15=Q$14,"✔","") | ... AC15: =IF($I15=AC$14,"✔","") | AD15: A
A16: 2 | B16: Prototipo del administrador (16 pantallas) | C16: Diseño | D16: Matías Negrete | E16: 4 | G16: 46289 | H16: Hecho | I16: 46292 | J16: =IF($I16=J$14,"✔","") | K16: =IF($I16=K$14,"✔","") | L16: =IF($I16=L$14,"✔","") | M16: =IF($I16=M$14,"✔","") -> ✔ | N16: =IF($I16=N$14,"✔","") | O16: =IF($I16=O$14,"✔","") | P16: =IF($I16=P$14,"✔","") | Q16: =IF($I16=Q$14,"✔","") | ... AC16: =IF($I16=AC$14,"✔","") | AD16: A
A17: 3 | B17: Semáforo del informe en las pantallas y rol Analista | C17: Diseño | D17: Matías Negrete | E17: 2 | G17: 46289 | H17: Hecho | I17: 46293 | J17: =IF($I17=J$14,"✔","") | K17: =IF($I17=K$14,"✔","") | L17: =IF($I17=L$14,"✔","") | M17: =IF($I17=M$14,"✔","") | N17: =IF($I17=N$14,"✔","") -> ✔ | O17: =IF($I17=O$14,"✔","") | P17: =IF($I17=P$14,"✔","") | Q17: =IF($I17=Q$14,"✔","") | ... AC17: =IF($I17=AC$14,"✔","") | AD17: A
A18: 4 | B18: Procesos AS-IS y TO-BE en BPMN (20 diagramas) | C18: Diseño | D18: Matías Negrete | E18: 3 | G18: 46289 | H18: Hecho | I18: 46293 | J18: =IF($I18=J$14,"✔","") | K18: =IF($I18=K$14,"✔","") | L18: =IF($I18=L$14,"✔","") | M18: =IF($I18=M$14,"✔","") | N18: =IF($I18=N$14,"✔","") -> ✔ | O18: =IF($I18=O$14,"✔","") | P18: =IF($I18=P$14,"✔","") | Q18: =IF($I18=Q$14,"✔","") | ... AC18: =IF($I18=AC$14,"✔","") | AD18: A
A19: 5 | B19: Vistas 4+1 en draw.io (6 páginas) | C19: Diseño | D19: Matías Negrete | E19: 3 | G19: 46289 | H19: Hecho | I19: 46293 | J19: =IF($I19=J$14,"✔","") | K19: =IF($I19=K$14,"✔","") | L19: =IF($I19=L$14,"✔","") | M19: =IF($I19=M$14,"✔","") | N19: =IF($I19=N$14,"✔","") -> ✔ | O19: =IF($I19=O$14,"✔","") | P19: =IF($I19=P$14,"✔","") | Q19: =IF($I19=Q$14,"✔","") | ... AC19: =IF($I19=AC$14,"✔","") | AD19: A
A20: 6 | B20: Informe: UX/UI, seguridad e integraciones | C20: Documentación | D20: Matías Negrete | E20: 2 | G20: 46289 | H20: Hecho | I20: 46293 | J20: =IF($I20=J$14,"✔","") | K20: =IF($I20=K$14,"✔","") | L20: =IF($I20=L$14,"✔","") | M20: =IF($I20=M$14,"✔","") | N20: =IF($I20=N$14,"✔","") -> ✔ | O20: =IF($I20=O$14,"✔","") | P20: =IF($I20=P$14,"✔","") | Q20: =IF($I20=Q$14,"✔","") | ... AC20: =IF($I20=AC$14,"✔","") | AD20: A
A21: 7 | B21: Informe: secciones F a M y Conclusión | C21: Documentación | D21: Matías Negrete | E21: 2 | G21: 46289 | H21: Hecho | I21: 46294 | J21: =IF($I21=J$14,"✔","") | K21: =IF($I21=K$14,"✔","") | L21: =IF($I21=L$14,"✔","") | M21: =IF($I21=M$14,"✔","") | N21: =IF($I21=N$14,"✔","") | O21: =IF($I21=O$14,"✔","") -> ✔ | P21: =IF($I21=P$14,"✔","") | Q21: =IF($I21=Q$14,"✔","") | ... AC21: =IF($I21=AC$14,"✔","") | AD21: A
A22: 8 | B22: Modelo de base de datos: diagrama ER y script SQL de referencia | C22: Documentación | D22: Matías Negrete | E22: 2 | G22: 46289 | H22: Hecho | I22: 46294 | J22: =IF($I22=J$14,"✔","") | K22: =IF($I22=K$14,"✔","") | L22: =IF($I22=L$14,"✔","") | M22: =IF($I22=M$14,"✔","") | N22: =IF($I22=N$14,"✔","") | O22: =IF($I22=O$14,"✔","") -> ✔ | P22: =IF($I22=P$14,"✔","") | Q22: =IF($I22=Q$14,"✔","") | ... AC22: =IF($I22=AC$14,"✔","") | AD22: A
A23: 9 | B23: Informe: secciones E, F, G y H con planilla de tablas | C23: Documentación | D23: Matías Negrete | E23: 3 | G23: 46295 | H23: Hecho | I23: 46299 | J23: =IF($I23=J$14,"✔","") | K23: =IF($I23=K$14,"✔","") | L23: =IF($I23=L$14,"✔","") | M23: =IF($I23=M$14,"✔","") | N23: =IF($I23=N$14,"✔","") | O23: =IF($I23=O$14,"✔","") | P23: =IF($I23=P$14,"✔","") | Q23: =IF($I23=Q$14,"✔","") | ... AC23: =IF($I23=AC$14,"✔","") | AD23: A
A24: 10 | B24: Documentos de dirección del proyecto (12 plantillas: acta, alcance, EDT, presupuesto y planes) | C24: Documentación | D24: Matías Negrete | E24: 3 | G24: 46298 | H24: Hecho | J24: =IF($I24=J$14,"✔","") | K24: =IF($I24=K$14,"✔","") | L24: =IF($I24=L$14,"✔","") | M24: =IF($I24=M$14,"✔","") | N24: =IF($I24=N$14,"✔","") | O24: =IF($I24=O$14,"✔","") | P24: =IF($I24=P$14,"✔","") | Q24: =IF($I24=Q$14,"✔","") | ... AC24: =IF($I24=AC$14,"✔","") | AD24: A
B25: Total | E25: =SUM(E15:E24) -> 28 | F25: =SUM(F15:F24) -> 0 | H25: =COUNTIF(H15:H24,"Hecho")&" hechas" -> 10 hechas
A27: Burndown del sprint
A28: Día | B28: Fecha | C28: Ideal | D28: Pendientes
A29: 0 | B29: inicio | C29: =IF($C$10=0,"",ROUND($C$10-$C$10*A29/20,1)) -> 8 | D29: 8
A30: 1 | B30: 24-09 | C30: =IF($C$10=0,"",ROUND($C$10-$C$10*A30/20,1)) -> 7.6 | D30: 8
A31: 2 | B31: 25-09 | C31: =IF($C$10=0,"",ROUND($C$10-$C$10*A31/20,1)) -> 7.2 | D31: 7
A32: 3 | B32: 26-09 | C32: =IF($C$10=0,"",ROUND($C$10-$C$10*A32/20,1)) -> 6.8 | D32: 7
A33: 4 | B33: 27-09 | C33: =IF($C$10=0,"",ROUND($C$10-$C$10*A33/20,1)) -> 6.4 | D33: 6
A34: 5 | B34: 28-09 | C34: =IF($C$10=0,"",ROUND($C$10-$C$10*A34/20,1)) -> 6 | D34: 2
A35: 6 | B35: 29-09 | C35: =IF($C$10=0,"",ROUND($C$10-$C$10*A35/20,1)) -> 5.6 | D35: 0
A36: 7 | B36: 30-09 | C36: =IF($C$10=0,"",ROUND($C$10-$C$10*A36/20,1)) -> 5.2 | D36: 1
A37: 8 | B37: 01-10 | C37: =IF($C$10=0,"",ROUND($C$10-$C$10*A37/20,1)) -> 4.8 | D37: 1
A38: 9 | B38: 02-10 | C38: =IF($C$10=0,"",ROUND($C$10-$C$10*A38/20,1)) -> 4.4 | D38: 1
A39: 10 | B39: 03-10 | C39: =IF($C$10=0,"",ROUND($C$10-$C$10*A39/20,1)) -> 4 | D39: 2
A40: 11 | B40: 04-10 | C40: =IF($C$10=0,"",ROUND($C$10-$C$10*A40/20,1)) -> 3.6 | D40: 1
A41: 12 | B41: 05-10 | C41: =IF($C$10=0,"",ROUND($C$10-$C$10*A41/20,1)) -> 3.2
A42: 13 | B42: 06-10 | C42: =IF($C$10=0,"",ROUND($C$10-$C$10*A42/20,1)) -> 2.8
A43: 14 | B43: 07-10 | C43: =IF($C$10=0,"",ROUND($C$10-$C$10*A43/20,1)) -> 2.4
...

Sheet H6 Scrum Board
A1: Scrum Board · sprints en curso (3, 5, 6) al 04-10-2026
A4: Por hacer (11) | B4: En curso (5) | C4: Hecho (17)
A5: S5 · 8. Panel del administrador: resumen de los últimos 7 días Entregable 15 · José P. | B5: S3 · 10. Documentos de dirección del proyecto (12 plantillas: acta, alcance, EDT, presupuesto y planes) Documentación · Matías N. | C5: S3 · 1. Prototipo de la app pública (11 pantallas) Diseño · Matías N. · 25-09
A6: S5 · 9. Anuncios del administrador y notificaciones del inversionista HU-18 · HU-14 · José P. | B6: S5 · 10. Perfil del inversionista y cambio de contraseña HU-12 · José P. | C6: S3 · 2. Prototipo del administrador (16 pantallas) Diseño · Matías N. · 27-09
A7: S5 · 13. Encabezado de la web en celular DEF-07 · José P. | B7: S5 · 11. Mapa de remates por comuna HU-15 · Basthian B. | C7: S3 · 3. Semáforo del informe en las pantallas y rol Analista Diseño · Matías N. · 28-09
